<?xml version="1.0" encoding="utf-8"?>
<!-- This URDF was automatically created by SolidWorks to URDF Exporter! Originally created by Stephen Brawner (brawner@gmail.com) 
     Commit Version: 1.6.0-4-g7f85cfe  Build Version: 1.6.7995.38578
     For more information, please see http://wiki.ros.org/sw_urdf_exporter -->
<robot
  name="wfs">
  <link
    name="base_link">
      <origin xyz="-0.014337 1.1818E-06 -0.0061469" rpy="0 0 0" />
    <inertial>
      <mass value="1.5" />
      <origin xyz="0 0 0" rpy="0 0 0" />
      <inertia ixx="0.0011526" ixy="-5.7288E-08" ixz="0.00022324" iyy="0.0020641" iyz="4.2737E-08" izz="0.0023957" />
    </inertial>
    
    <visual>
      <origin
        xyz="0 0 0"
         rpy="-1.5708 0 0" />
      <geometry>
        <mesh
          filename="../meshes/base_link.STL" />
      </geometry>
      <material
        name="">
        <color
          rgba="0.949 0.85 0.349 1" />
      </material>
    </visual>
        <sensor name="accelerometer" type="imu">
      <origin xyz="0 0 0" rpy="0 0 0"/>
      <imu>
        <linear_acceleration>
          <noise type="gaussian">
            <mean>0.0</mean>
            <stddev>0.01</stddev>
          </noise>
        </linear_acceleration>
      </imu>
    </sensor>
    <collision>
      <origin
        xyz="0 0 0"
        rpy="0 0 0" />
      <geometry>
        <mesh
          filename="../meshes/base_link.STL" />
      </geometry>
    </collision>
  </link>
  <link
    name="la">
    <inertial>
      <origin
        xyz="-0.033704 -0.010899 -0.020545"
        rpy="0 0 0" />
      <mass
        value="0.7" />
      <inertia
        ixx="0.00019193"
        ixy="1.2227E-05"
        ixz="-0.00018272"
        iyy="0.00051959"
        iyz="7.4461E-06"
        izz="0.00033865" />
    </inertial>
    <visual>
      <origin
        xyz="0 0 0"
        rpy="-1.5708 0 0" />
      <geometry>
        <mesh
          filename="../meshes/la.STL" />
      </geometry>
      <material
        name="">
        <color
          rgba="0.902 0.902 0.902 1" />
      </material>
    </visual>
    <collision>
      <origin
        xyz="0 0 0"
        rpy="0 0 0" />
      <geometry>
        <mesh
          filename="../meshes/la.STL" />
      </geometry>
    </collision>
  </link>
  <joint
    name="laj"
    type="revolute">
    <origin
      xyz="-0.014207 0.1052 -0.0465"
      rpy="0 0 0" />
    <parent
      link="base_link" />
    <child
      link="la" />
    <axis
      xyz="0 -1 0" />
    <limit
      lower="-0.8"
      upper="2.0"
      effort="12"
      velocity="25.12" />
  </joint>
  <link
    name="ll">
    <inertial>
      <origin
        xyz="0.054145 0.0083245 -0.063627"
        rpy="0 0 0" />
      <mass
        value="0.28" />
      <inertia
        ixx="0.0002644"
        ixy="-4.2542E-05"
        ixz="0.00024918"
        iyy="0.00057209"
        iyz="3.4902E-05"
        izz="0.00033434" />
    </inertial>
    <visual>
      <origin
        xyz="0 0 0"
         rpy="-1.5708 0 0" />
      <geometry>
        <mesh
          filename="../meshes/ll.STL" />
      </geometry>
      <material
        name="">
        <color
          rgba="0.7137 0.7059 0.7059 1" />
      </material>
    </visual>
    <collision>
      <origin
        xyz="0 0 0"
        rpy="0 0 0" />
      <geometry>
        <mesh
          filename="../meshes/ll.STL" />
      </geometry>
    </collision>
  </link>
  <joint
    name="llj"
    type="revolute">
    <origin
      xyz="-0.11545 -0.0075 -0.11166"
      rpy="0 0 0" />
    <parent
      link="la" />
    <child
      link="ll" />
    <axis
      xyz="0 1 0" />
    <limit
      lower="-1.0"
      upper="0.68"
      effort="12."
      velocity="25.12." />
  </joint>
  <link
    name="lw">
    <inertial>
      <origin
        xyz="-1.4311E-05 0.027855 -1.1802E-05"
        rpy="0 0 0" />
      <mass
        value="0.832" />
      <inertia
        ixx="0.0012191"
        ixy="-1.4288E-07"
        ixz="1.8574E-07"
        iyy="0.0022205"
        iyz="-1.1784E-07"
        izz="0.001219" />
    </inertial>
    <visual>
      <origin
        xyz="0 0 0"
        rpy="-1.5708 0 0" />
      <geometry>
        <mesh
          filename="../meshes/lw.STL" />
      </geometry>
      <material
        name="">
        <color
          rgba="0.5 0.5 0.6 1" />
      </material>
    </visual>
    <collision>
      <origin
        xyz="0 0 0"
        rpy="0 0 0" />
      <geometry>
        <mesh
          filename="../meshes/lw.STL" />
      </geometry>
    </collision>
  </link>
  <joint
    name="lwj"
    type="revolute">
    <origin
      xyz="0.13092 0.027 -0.12321"
      rpy="0 0 0" />
    <parent
      link="ll" />
    <child
      link="lw" />
    <axis
      xyz="0 -1 0" />
    <limit
      effort="2."
      velocity="33.49" />
  </joint>
  <link
    name="ra">
    <inertial>
      <origin
        xyz="-0.033704 0.010899 -0.020545"
        rpy="0 0 0" />
      <mass
        value="0.7" />
      <inertia
        ixx="0.00019193"
        ixy="-1.2227E-05"
        ixz="-0.00018272"
        iyy="0.0005196"
        iyz="-7.4461E-06"
        izz="0.00033866" />
    </inertial>
    <visual>
      <origin
        xyz="0 0 0"
        rpy="-1.5708 0 0" />
      <geometry>
        <mesh
          filename="../meshes/ra.STL" />
      </geometry>
      <material
        name="">
        <color
          rgba="0.902 0.902 0.902 1" />
      </material>
    </visual>
    <collision>
      <origin
        xyz="0 0 0"
        rpy="0 0 0" />
      <geometry>
        <mesh
          filename="../meshes/ra.STL" />
      </geometry>
    </collision>
  </link>
  <joint
    name="raj"
    type="revolute">
    <origin
      xyz="-0.014207 -0.1052 -0.0465"
      rpy="0 0 0" />
    <parent
      link="base_link" />
    <child
      link="ra" />
    <axis
      xyz="0 1 0" />
    <limit
      lower="-0.8"
      upper="2."
      effort="12."
      velocity="25.12." />
  </joint>
  <link
    name="rl">
    <inertial>
      <origin
        xyz="0.054146 -0.0083247 -0.063628"
        rpy="0 0 0" />
      <mass
        value="0.28" />
      <inertia
        ixx="0.00026441"
        ixy="4.2543E-05"
        ixz="0.00024918"
        iyy="0.00057211"
        iyz="-3.4903E-05"
        izz="0.00033435" />
    </inertial>
    <visual>
      <origin
        xyz="0 0 0"
        rpy="-1.5708 0 0" />
      <geometry>
        <mesh
          filename="../meshes/rl.STL" />
      </geometry>
      <material
        name="">
        <color
          rgba="0.7137 0.7059 0.7059 1" />
      </material>
    </visual>
    <collision>
      <origin
        xyz="0 0 0"
        rpy="0 0 0" />
      <geometry>
        <mesh
          filename="../meshes/rl.STL" />
      </geometry>
    </collision>
  </link>
  <joint
    name="rlj"
    type="revolute">
    <origin
      xyz="-0.11545 0.0075 -0.11166"
      rpy="0 0 0" />
    <parent
      link="ra" />
    <child
      link="rl" />
    <axis
      xyz="0 -1 0" />
    <limit
      lower="-0.68"
      upper="1.0"
      effort="12"
      velocity="25.12." />
  </joint>
  <link
    name="rw">
    <inertial>
      <origin
        xyz="-1.4311E-05 -0.027855 -1.1802E-05"
        rpy="0 0 0" />
      <mass
        value="0.832" />
      <inertia
        ixx="0.0012191"
        ixy="1.4288E-07"
        ixz="1.8574E-07"
        iyy="0.0022205"
        iyz="1.1784E-07"
        izz="0.001219" />
    </inertial>
    <visual>
      <origin
        xyz="0 0 0"
        rpy="-1.5708 0 0" />
      <geometry>
        <mesh
          filename="../meshes/rw.STL" />
      </geometry>
      <material
        name="">
        <color
          rgba="0.5 0.5 0.6 1" />
      </material>
    </visual>
    <collision>
      <origin
        xyz="0 0 0"
        rpy="0 0 0" />
      <geometry>
        <mesh
          filename="../meshes/rw.STL" />
      </geometry>
    </collision>
  </link>
  <joint
    name="rwj"
    type="revolute">
    <origin
      xyz="0.13092 -0.027 -0.12321"
      rpy="0 0 0" />
    <parent
      link="rl" />
    <child
      link="rw" />
    <axis
      xyz="0 1 0" />
    <limit
       effort="2."
      velocity="33.49" />
  </joint>
</robot>